Workbook

Sheet EEFF
A1: Estados Financieros — EEFF
A2: BANCO BBVA PERU · Cifras en miles de Soles · Fuente: SMV (Consolidado) · Proyección 2026-2035 con fórmulas vivas. Herramienta educativa, no es asesoría financiera.
C3: HISTÓRICO | K3: PROYECCIÓN | V3: ANÁLISIS VERTICAL (%)
A4: Cuenta | C4: 2018 | D4: 2019 | E4: 2020 | F4: 2021 | G4: 2022 | H4: 2023 | I4: 2024 | J4: 2025 | K4: 2026 | L4: 2027 | M4: 2028 | N4: 2029 | O4: 2030 | P4: 2031 | Q4: 2032 | R4: 2033 | S4: 2034 | T4: 2035 | V4: 2018 | W4: 2019 | X4: 2020 | Y4: 2021 | Z4: 2022 | AA4: 2023 | AB4: 2024 | AC4: 2025 | AD4: 2026 | AE4: 2027 | AF4: 2028 | AG4: 2029 | AH4: 2030 | AI4: 2031 | AJ4: 2032 | AK4: 2033 | AL4: 2034 | AM4: 2035
A5: ESTADO DE RESULTADOS
A6: Ingresos de Actividades Ordinarias | C6: 4483439 | D6: 4796546 | E6: 4298555 | F6: 4236841 | G6: 5739163 | H6: 7585895 | I6: 8083186 | J6: 7967004 | K6: =J6*(1+Supuestos!$C$7) | L6: =K6*(1+Supuestos!$C$7) | M6: =L6*(1+Supuestos!$C$7) | N6: =M6*(1+Supuestos!$C$7) | O6: =N6*(1+Supuestos!$C$7) | P6: =O6*(1+Supuestos!$C$7) | Q6: =P6*(1+Supuestos!$C$7) | R6: =Q6*(1+Supuestos!$C$7) | ... T6: =S6*(1+Supuestos!$C$7) | V6: =C6/C6 | W6: =D6/D6 | X6: =E6/E6 | Y6: =F6/F6 | Z6: =G6/G6 | AA6: =H6/H6 | AB6: =I6/I6 | AC6: =J6/J6 | ... AM6: =T6/T6
A7: Resultado de Operación | C7: 2047244 | D7: 2217221 | E7: 908225 | F7: 2263027 | G7: 2661616 | H7: 2359535 | I7: 2397717 | J7: 3291004 | V7: =C7/C6 | W7: =D7/D6 | X7: =E7/E6 | Y7: =F7/F6 | Z7: =G7/G6 | AA7: =H7/H6 | AB7: =I7/I6 | AC7: =J7/J6
A8: Gasto por Impuesto a las Ganancias | C8: -567778 | D8: -630207 | E8: -239167 | F8: -691722 | G8: -753863 | H8: -559826 | I8: -541536 | J8: -895320 | V8: =C8/C6 | W8: =D8/D6 | X8: =E8/E6 | Y8: =F8/F6 | Z8: =G8/G6 | AA8: =H8/H6 | AB8: =I8/I6 | AC8: =J8/J6
A9: Resultado Neto del Ejercicio | C9: 1468926 | D9: 1609056 | E9: 648216 | F9: 1560500 | G9: 1921759 | H9: 1873736 | I9: 1882772 | J9: 2390911 | K9: =J9*(1+Supuestos!$C$7) | L9: =K9*(1+Supuestos!$C$7) | M9: =L9*(1+Supuestos!$C$7) | N9: =M9*(1+Supuestos!$C$7) | O9: =N9*(1+Supuestos!$C$7) | P9: =O9*(1+Supuestos!$C$7) | Q9: =P9*(1+Supuestos!$C$7) | R9: =Q9*(1+Supuestos!$C$7) | ... T9: =S9*(1+Supuestos!$C$7) | V9: =C9/C6 | W9: =D9/D6 | X9: =E9/E6 | Y9: =F9/F6 | Z9: =G9/G6 | AA9: =H9/H6 | AB9: =I9/I6 | AC9: =J9/J6 | ... AM9: =T9/T6
A11: BALANCE GENERAL (proyección: solo patrimonio)
A12: TOTAL ACTIVO | C12: 74982718 | D12: 81778899 | E12: 107337268 | F12: 101495755 | G12: 98045446 | H12: 104323802 | I12: 111188992 | J12: 112336347 | V12: =C12/C12 | W12: =D12/D12 | X12: =E12/E12 | Y12: =F12/F12 | Z12: =G12/G12 | AA12: =H12/H12 | AB12: =I12/I12 | AC12: =J12/J12
A13: TOTAL PASIVO | C13: 66630505 | D13: 72598433 | E13: 97975412 | F13: 91327026 | G13: 86792072 | H13: 91954134 | I13: 97888646 | J13: 97344718 | V13: =C13/C12 | W13: =D13/D12 | X13: =E13/E12 | Y13: =F13/F12 | Z13: =G13/G12 | AA13: =H13/H12 | AB13: =I13/I12 | AC13: =J13/J12
A14: TOTAL PATRIMONIO | C14: 8352213 | D14: 9180466 | E14: 9361856 | F14: 10168729 | G14: 11253374 | H14: 12369668 | I14: 13300346 | J14: 14991629 | K14: =J14+K9*(1-Supuestos!$C$14) | L14: =K14+L9*(1-Supuestos!$C$14) | M14: =L14+M9*(1-Supuestos!$C$14) | N14: =M14+N9*(1-Supuestos!$C$14) | O14: =N14+O9*(1-Supuestos!$C$14) | P14: =O14+P9*(1-Supuestos!$C$14) | Q14: =P14+Q9*(1-Supuestos!$C$14) | R14: =Q14+R9*(1-Supuestos!$C$14) | ... T14: =S14+T9*(1-Supuestos!$C$14) | V14: =C14/C12 | W14: =D14/D12 | X14: =E14/E12 | Y14: =F14/F12 | Z14: =G14/G12 | AA14: =H14/H12 | AB14: =I14/I12 | AC14: =J14/J12 | ... AM14: =T14/T12
A15: Empresa financiera: proyección de FCFF/FCFE no aplica (capex y capital de trabajo no son separables del negocio). Solo se proyecta lo necesario para el DDM.
A17: FLUJO DE EFECTIVO
A18: Dividendos Pagados | C18: -761550 | D18: -810470 | E18: -562761 | F18: -601232 | G18: -778101 | H18: -955356 | I18: -933163 | J18: -940958
A19: Dividendos Pagados (proyección) | K19: =-Supuestos!$C$14*K9 | L19: =-Supuestos!$C$14*L9 | M19: =-Supuestos!$C$14*M9 | N19: =-Supuestos!$C$14*N9 | O19: =-Supuestos!$C$14*O9 | P19: =-Supuestos!$C$14*P9 | Q19: =-Supuestos!$C$14*Q9 | R19: =-Supuestos!$C$14*R9 | ... T19: =-Supuestos!$C$14*T9

Sheet Supuestos
A1: Supuestos — BANCO BBVA PERU
A2: Única hoja editable: las celdas azules son inputs; las negras son fórmulas por componentes (sobreescribibles). Defaults sujetos a revisión.
A4: Supuesto | C4: Valor | D4: Nota / fuente
A6: Operativos
A7: Crecimiento de ventas (g) | C7: =MAX(-0.15,MIN(0.25,(EEFF!J6/EEFF!C6)^(1/7)-1)) | D7: Fórmula viva: CAGR histórico de ventas (años disponibles), tope −15%/+25%; sobreescribible
A8: Costo de ventas % de ventas | C8: 0.6 | D8: Fórmula viva: promedio histórico |costo| / ventas
A9: Gastos adm. y ventas % de ventas | C9: 0.1 | D9: Fórmula viva: promedio histórico |gastos| / ventas
A10: D&A % de ventas | C10: 0.03324407 | D10: D&A 2024 = 268,718 miles (operaciones continuas) del EEFF auditado (prototipo_auditado_BBVA_2024.json, doble ruta cuadrada) ÷ ventas 2024; editable
A11: Capex % de ventas | C11: 0.03 | D11: Fórmula viva: promedio histórico |compras PPE + intangibles| / ventas
A12: Δ Capital de trabajo % de ventas | C12: 0 | D12: Fórmula viva: promedio histórico ΔKW / ventas (años consecutivos)
A13: Tasa impositiva efectiva (para proyección EGP) | C13: 0.295 | D13: Fórmula viva: promedio histórico |impuesto| / UAI, tope 0-50%
A14: Payout de dividendos | C14: =MAX(0,MIN(1,AVERAGE(ABS(EEFF!C18)/EEFF!C9,ABS(EEFF!D18)/EEFF!D9,ABS(EEFF!E18)/EEFF!E9,ABS(EEFF!F18)/EEFF!F9,ABS(EEFF!G18)/EEFF!G9,ABS(EEFF!H18)/EEFF!H9,ABS(EEFF!I18)/EEFF!I9,ABS(EEFF!J18)/EEFF!J9))) | D14: Fórmula viva: promedio histórico |dividendos| / utilidad neta
A15: ROE promedio histórico | C15: =AVERAGE(EEFF!C9/EEFF!C14,EEFF!D9/EEFF!D14,EEFF!E9/EEFF!E14,EEFF!F9/EEFF!F14,EEFF!G9/EEFF!G14,EEFF!H9/EEFF!H14,EEFF!I9/EEFF!I14,EEFF!J9/EEFF!J14) | D15: Fórmula viva: promedio histórico utilidad neta / patrimonio; insumo del g de dividendos (DDM)
A16: g dividendos = ROE × (1 − payout) | C16: =Supuestos!$C$15*(1-Supuestos!$C$14) | D16: Crecimiento fundamental de dividendos para el DDM (Gordon); sobreescribible
A18: Descuento — CAPM/WACC por componentes (fuentes: misma metodología valorización PANASA; defaults jul-2026, sujetos a revisión)
A19: Tasa libre de riesgo (rf) | C19: 0.0455 | D19: US Treasury 10Y — fuente: investing.com (capturado 15-jul-2026)
A20: EMBIG Perú (riesgo país) | C20: 0.0103 | D20: Fuente: BCRP serie PD04709XD (jul-2026)
A21: Ratio σ acciones / σ bonos | C21: 1.52 | D21: Deducido de Damodaran
A22: CRP = EMBIG × ratio | C22: =Supuestos!$C$20*Supuestos!$C$21 | D22: Country Risk Premium (sobreescribible)
A23: ERP mercado maduro | C23: 0.0423 | D23: Damodaran implied ERP jul-2026 (ctryprem.html); alternativa Kroll 5.0%
A24: Beta desapalancado sectorial (βu) | C24: 0.6 | D24: Damodaran betaemerg.xls (Emerging Markets, ene-2026) · Industria: Banks (Regional) · editable
A25: D/E contable de la empresa | C25: 0 | D25: Financiera: no aplica, se deja en 0
A26: Tasa IR estatutaria (Hamada, Kd) | C26: 0.295 | D26: Impuesto a la renta Perú 29.5%
A27: Beta reapalancado (βL) | C27: =Supuestos!$C$24 | D27: Financiera: Hamada no aplica (la deuda es el negocio); βL = β directo de la industria
A28: Costo de la deuda (Kd) | C28: 0.08 | D28: No calculable del histórico: default genérico 8%, revisar
A29: COK en US$ = rf + βL×ERP + CRP | C29: =Supuestos!$C$19+Supuestos!$C$27*Supuestos!$C$23+Supuestos!$C$22 | D29: Costo de oportunidad del accionista en dólares
A30: Inflación esperada S/ | C30: 0.025 | D30: Diferencial esperado; editable
A31: Inflación esperada US$ | C31: 0.025 | D31: Diferencial esperado; editable
A32: COK en S/ nominal | C32: =(1+Supuestos!$C$29)*(1+Supuestos!$C$30)/(1+Supuestos!$C$31)-1 | D32: (1+COK_US$)×(1+infl_S/)/(1+infl_US$) − 1
A33: Ke = COK S/ (para FCFE y DDM) | C33: =Supuestos!$C$32 | D33: Costo del patrimonio en la moneda de los EEFF (Soles)
A34: Deuda financiera (D) | C34: 0 | D34: Financiera: no aplica, se deja en 0
A35: Patrimonio (E contable) | C35: =EEFF!J14 | D35: Patrimonio 2025 (fórmula viva a EEFF)
A36: Patrimonio a mercado (market cap) | C36: =Supuestos!$C$35 | D36: Sin precio de mercado: fallback al patrimonio contable
A37: WACC | C37: =Supuestos!$C$33 | D37: Financiera: no se usa (solo DDM), se deja = Ke
A38: Crecimiento terminal (g) | C38: 0.03 | D38: Default simple, revisar (FCFF/FCFE; el DDM usa g dividendos)
A40: Mercado — acciones por clase y precios
A41: Tipo de cambio (S/ por US$) | C41: 3.7 | D41: Para convertir precios de mercado a la moneda de los EEFF (Soles); editable
A42: Precio acción común (moneda de cotización) | D42: Sin dato automático (red/BVL); ingresar manualmente
A43: Precio acción común en Soles (EEFF) | D43: Convertido con el tipo de cambio si la cotización es en otra moneda
A44: Acciones comunes (miles) | C44: 9649407.9 | D44: Default: Utilidad neta / EPS básica 2025; editable
...

Sheet Valorización
A1: Valorización — BANCO BBVA PERU
A2: Cifras en miles de Soles (precio por acción en Soles). FCFF/FCFE descuentan al WACC/Ke; DDM al Ke.
A4: FCFF — DCF EMPRESARIAL
A5: N/A — financiera (capex y capital de trabajo no son separables del negocio)
A7: FCFE — DCF PATRIMONIAL
A8: N/A — financiera (capex y capital de trabajo no son separables del negocio)
A10: DDM — MODELO DE GORDON
A11: Año | C11: 2026 | D11: 2027 | E11: 2028 | F11: 2029 | G11: 2030 | H11: 2031 | I11: 2032 | J11: 2033 | K11: 2034 | L11: 2035
A12: Dividendos | C12: =-EEFF!K19 | D12: =-EEFF!L19 | E12: =-EEFF!M19 | F12: =-EEFF!N19 | G12: =-EEFF!O19 | H12: =-EEFF!P19 | I12: =-EEFF!Q19 | J12: =-EEFF!R19 | ... L12: =-EEFF!T19
A13: Dividendos | C13: =SUM(C12:C12) | D13: =SUM(D12:D12) | E13: =SUM(E12:E12) | F13: =SUM(F12:F12) | G13: =SUM(G12:G12) | H13: =SUM(H12:H12) | I13: =SUM(I12:I12) | J13: =SUM(J12:J12) | ... L13: =SUM(L12:L12)
A14: Factor de descuento | C14: =1/(1+Supuestos!$C$33)^1 | D14: =1/(1+Supuestos!$C$33)^2 | E14: =1/(1+Supuestos!$C$33)^3 | F14: =1/(1+Supuestos!$C$33)^4 | G14: =1/(1+Supuestos!$C$33)^5 | H14: =1/(1+Supuestos!$C$33)^6 | I14: =1/(1+Supuestos!$C$33)^7 | J14: =1/(1+Supuestos!$C$33)^8 | K14: =1/(1+Supuestos!$C$33)^9 | L14: =1/(1+Supuestos!$C$33)^10
A15: PV del dividendos | C15: =C13*C14 | D15: =D13*D14 | E15: =E13*E14 | F15: =F13*F14 | G15: =G13*G14 | H15: =H13*H14 | I15: =I13*I14 | J15: =J13*J14 | ... L15: =L13*L14
A17: Suma PV dividendos 2026-2035 | C17: =SUM(C15:L15)
A18: Valor terminal (Gordon) | C18: =L13*(1+Supuestos!$C$16)/(Supuestos!$C$33-Supuestos!$C$16)
A19: PV del valor terminal | C19: =C18*L14
A20: Valor del patrimonio (equity) | C20: =C17+C19
A21: Precio implícito por acción (dividendos) | C21: =C20/Supuestos!$C$49
A24: RESUMEN — PRECIO IMPLÍCITO VS MERCADO
A25: Modelo | C25: Precio implícito | D25: Precio mercado | E25: Upside vs mercado
A26: FCFF (DCF empresarial) | C26: N/A — financiera | D26: =Supuestos!$C$43
A27: FCFE (DCF patrimonial) | C27: N/A — financiera | D27: =Supuestos!$C$43
A28: DDM (Gordon) | C28: =C21 | D28: =Supuestos!$C$43 | E28: =C21/Supuestos!$C$43-1
